Workbook

Sheet Samples
A1: Tecan ID | B1: Magic ref. | C1: id | D1: DNA conc. [ng µl-1] | E1: DNA [µl] | F1: Amount DNA [ng] | G1: Water [µl] | H1: Cycles PCR | I1: Batch Magicprep | J1: Position strip | K1: DNA library [ng µl-1] | L1: Ref | M1: Comments
A2: 49 | B2: B3 | C2: l5u | D2: 0.469 | E2: =10/D2 -> 21.321962 | F2: =D2*E2 -> 10 | G2: =40-E2 -> 18.678038 | H2: 12 | I2: 5 | J2: 1 | K2: 25 | L2: 30188846/22460291
A3: 50 | B3: B3 | C3: cosc_f3 | D3: 0.688 | E3: =10/D3 -> 14.534884 | F3: =D3*E3 -> 10 | G3: =40-E3 -> 25.465116 | H3: 12 | I3: 5 | J3: 2 | K3: > 60 (1:1 49.8) | L3: 30188846/22460291
A4: 51 | B4: B3 | C4: cosc_f5 | D4: 0.424 | E4: =10/D4 -> 23.584906 | F4: =D4*E4 -> 10 | G4: =40-E4 -> 16.415094 | H4: 12 | I4: 5 | J4: 3 | K4: > 60 (1:1 36.5) | L4: 30188846/22460291
A5: 52 | B5: B3 | C5: a1u | D5: 0.123 | E5: 30 | F5: =D5*E5 -> 3.69 | G5: =40-E5 -> 10 | H5: 12 | I5: 5 | J5: 4 | K5: 3.1 | L5: 30188846/22460291
A6: 53 | B6: B3 | C6: a3u | D6: 0.07 | E6: 30 | F6: =D6*E6 -> 2.1 | G6: =40-E6 -> 10 | H6: 12 | I6: 5 | J6: 5 | K6: 0.089 | L6: 30188846/22460291
A7: 54 | B7: B3 | C7: s3f | D7: 0.202 | E7: 30 | F7: =D7*E7 -> 6.06 | G7: =40-E7 -> 10 | H7: 12 | I7: 5 | J7: 6 | K7: 1.28 | L7: 30188846/22460291
A8: 55 | B8: B3 | C8: l6f | D8: 0.17 | E8: 20 | F8: =D8*E8 -> 3.4 | G8: =40-E8 -> 20 | H8: 12 | I8: 5 | J8: 7 | K8: 9.14 | L8: 30188846/22460291
A9: 56 | B9: B3 | C9: l7f | D9: 0.305 | E9: 20 | F9: =D9*E9 -> 6.1 | G9: =40-E9 -> 20 | H9: 12 | I9: 5 | J9: 8 | K9: 2.86 | L9: 30188846/22460291
A10: 41 | B10: B2 | C10: cosc_f1 | D10: 1.65 | E10: =20/D10 -> 12.121212 | F10: 20 | G10: =40-E10 -> 27.878788 | H10: 10 | I10: 4 | J10: 1 | K10: 56 | L10: 30188845/22460290
A11: 42 | B11: B2 | C11: media_control | D11: < 0.05 | E11: 30 | F11: 0 | G11: =40-E11 -> 10 | H11: 10 | I11: 4 | J11: 2 | K11: 0.248 | L11: 30188845/22460290
A12: 43 | B12: B2 | C12: l1f | D12: 1.9 | E12: =20/D12 -> 10.526316 | F12: 20 | G12: =40-E12 -> 29.473684 | H12: 10 | I12: 4 | J12: 3 | K12: 36.5 | L12: 30188845/22460290
A13: 44 | B13: B2 | C13: l2u | D13: 1.39 | E13: =20/D13 -> 14.388489 | F13: 20 | G13: =40-E13 -> 25.611511 | H13: 10 | I13: 4 | J13: 4 | K13: 53 | L13: 30188845/22460290
A14: 45 | B14: B2 | C14: a4u | D14: 1.79 | E14: =20/D14 -> 11.173184 | F14: 20 | G14: =40-E14 -> 28.826816 | H14: 10 | I14: 4 | J14: 5 | K14: 48.8 | L14: 30188845/22460290
A15: 46 | B15: B2 | C15: s2u | D15: 1.28 | E15: =20/D15 -> 15.625 | F15: 20 | G15: =40-E15 -> 24.375 | H15: 10 | I15: 4 | J15: 6 | K15: 43.3 | L15: 30188845/22460290
A16: 47 | B16: B2 | C16: media+oil_b | D16: 12.3 | E16: =20/D16 -> 1.6260163 | F16: =D16*E16 -> 20 | G16: =40-E16 -> 38.373984 | H16: 10 | I16: 4 | J16: 7 | K16: 8.05 | L16: 30188845/22460290
A17: 48 | B17: B2 | C17: KFM02a_control | D17: < 0.05 | E17: 30 | F17: 0 | G17: =40-E17 -> 10 | H17: 10 | I17: 4 | J17: 8 | K17: < 0.05 | L17: 30188845/22460290
A18: 33 | B18: B1 | C18: l3u | D18: 3.77 | E18: =80/D18 -> 21.220159 | F18: =D18*E18 -> 80 | G18: =40-E18 -> 18.779841 | H18: 7 | I18: 3 | J18: 1 | K18: 29.8 | L18: 30188844/22460341
A19: 34 | B19: B1 | C19: l2f | D19: 2.84 | E19: =80/D19 -> 28.169014 | F19: =D19*E19 -> 80 | G19: =40-E19 -> 11.830986 | H19: 7 | I19: 3 | J19: 2 | K19: 54 | L19: 30188844/22460341
A20: 35 | B20: B1 | C20: a4f | D20: 2.9 | E20: =80/D20 -> 27.586207 | F20: =D20*E20 -> 80 | G20: =40-E20 -> 12.413793 | H20: 7 | I20: 3 | J20: 3 | K20: 3 | L20: 30188844/22460341
A21: 36 | B21: B1 | C21: KFM02a_2 | D21: 3.28 | E21: =80/D21 -> 24.390244 | F21: =D21*E21 -> 80 | G21: =40-E21 -> 15.609756 | H21: 7 | I21: 3 | J21: 4 | K21: > 60 (1:1 35.9) | L21: 30188844/22460341
A22: 37 | B22: B1 | C22: KFM24_1 | D22: 2.35 | E22: =80/D22 -> 34.042553 | F22: =D22*E22 -> 80 | G22: =40-E22 -> 5.9574468 | H22: 7 | I22: 3 | J22: 5 | K22: 43.4 | L22: 30188844/22460341
A23: 38 | B23: B1 | C23: KFM24_2 | D23: 3.66 | E23: =80/D23 -> 21.857923 | F23: =D23*E23 -> 80 | G23: =40-E23 -> 18.142077 | H23: 7 | I23: 3 | J23: 6 | K23: 30.2 | L23: 30188844/22460341
A24: 39 | B24: B1 | C24: KFM24_3 | D24: 4.21 | E24: =80/D24 -> 19.002375 | F24: =D24*E24 -> 80 | G24: =40-E24 -> 20.997625 | H24: 7 | I24: 3 | J24: 7 | K24: 52 | L24: 30188844/22460341
A25: 40 | B25: B1 | C25: media+gw+oil_c | D25: 2.52 | E25: =80/D25 -> 31.746032 | F25: =D25*E25 -> 80 | G25: =40-E25 -> 8.2539683 | H25: 7 | I25: 3 | J25: 8 | K25: 0.357 | L25: 30188844/22460341
A26: 57 | B26: B4 | C26: methanol_d | D26: 19.1 | E26: =80/D26 -> 4.1884817 | F26: =D26*E26 -> 80 | G26: =40-E26 -> 35.811518 | H26: 7 | I26: 6 | J26: 1 | K26: 8.81 | L26: 30188847/22460292 | M26: A4 deck failed due to wrong beads (batch 2)
A27: 58 | B27: B4 | C27: media+gw+oil_c | D27: 2.52 | E27: =80/D27 -> 31.746032 | F27: =D27*E27 -> 80 | G27: =40-E27 -> 8.2539683 | H27: 7 | I27: 6 | J27: 2 | K27: > 60 (1:1 52.0) | L27: 30188847/22460292
A28: 59 | B28: B4 | C28: media+gw+oil_b | D28: 6.7 | E28: =80/D28 -> 11.940299 | F28: =D28*E28 -> 80 | G28: =40-E28 -> 28.059701 | H28: 7 | I28: 6 | J28: 3 | K28: 51 | L28: 30188847/22460292
A29: 60 | B29: B4 | C29: a1f | D29: 5.16 | E29: =80/D29 -> 15.503876 | F29: =D29*E29 -> 80 | G29: =40-E29 -> 24.496124 | H29: 7 | I29: 6 | J29: 4 | K29: > 60 (1:1 39.7) | L29: 30188847/22460292
A30: 61 | B30: B4 | C30: KFM02a_3 | D30: 5.9 | E30: =80/D30 -> 13.559322 | F30: =D30*E30 -> 80 | G30: =40-E30 -> 26.440678 | H30: 7 | I30: 6 | J30: 5 | K30: 56 | L30: 30188847/22460292
A31: 62 | B31: B4 | C31: KFM02a_5 | D31: 6.1 | E31: =80/D31 -> 13.114754 | F31: =D31*E31 -> 80 | G31: =40-E31 -> 26.885246 | H31: 7 | I31: 6 | J31: 6 | K31: > 60 (1:1 52.0) | L31: 30188847/22460292
A32: 63 | B32: B4 | C32: SA1420_srma | D32: 10.4 | E32: =80/D32 -> 7.6923077 | F32: =D32*E32 -> 80 | G32: =40-E32 -> 32.307692 | H32: 7 | I32: 6 | J32: 7 | K32: > 60 (1:1 56.0) | L32: 30188847/22460292
A33: 64 | B33: B4 | C33: SA1420_srmb | D33: 9.58 | E33: =80/D33 -> 8.3507307 | F33: =D33*E33 -> 80 | G33: =40-E33 -> 31.649269 | H33: 7 | I33: 6 | J33: 8 | K33: 60 | L33: 30188847/22460292
A34: 17 | B34: A3 | C34: media+gw_a | D34: 17 | E34: =300/D34 -> 17.647059 | F34: 300 | G34: =40-E34 -> 22.352941 | H34: 4 | I34: 1 | J34: 1 | K34: > 60 (1:1 53.0) | L34: 3018832/22450191
A35: 18 | B35: A3 | C35: media+gw_b | D35: 11.5 | E35: =300/D35 -> 26.086957 | F35: 300 | G35: =40-E35 -> 13.913043 | H35: 4 | I35: 1 | J35: 2 | K35: > 60 (1:1 26.0) | L35: 3018832/22450191
A36: 19 | B36: A3 | C36: media+gw_d | D36: 23.3 | E36: =300/D36 -> 12.875536 | F36: 300 | G36: =40-E36 -> 27.124464 | H36: 4 | I36: 1 | J36: 3 | K36: 57 | L36: 3018832/22450191
A37: 20 | B37: A3 | C37: methanol_a | D37: 41.8 | E37: =300/D37 -> 7.1770335 | F37: 300 | G37: =40-E37 -> 32.822967 | H37: 4 | I37: 1 | J37: 4 | K37: 33.3 | L37: 3018832/22450191
A38: 21 | B38: A3 | C38: methanol_c | D38: 19.9 | E38: =300/D38 -> 15.075377 | F38: 300 | G38: =40-E38 -> 24.924623 | H38: 4 | I38: 1 | J38: 5 | K38: 33.5 | L38: 3018832/22450191
A39: 22 | B39: A3 | C39: methanol_d | D39: 19.1 | E39: =300/D39 -> 15.706806 | F39: =D39*E39 -> 300 | G39: =40-E39 -> 24.293194 | H39: 4 | I39: 1 | J39: 6 | K39: 0.35 | L39: 3018832/22450191 | M39: Failed due to wrong beads
A40: 23 | B40: A3 | C40: media+oil_b | D40: 12.3 | E40: =300/D40 -> 24.390244 | F40: =D40*E40 -> 300 | G40: =40-E40 -> 15.609756 | H40: 4 | I40: 1 | J40: 7 | K40: 0.31 | L40: 3018832/22450191 | M40: Failed due to wrong beads
...

Sheet Pool
A1: Tecan ID | B1: Sample | C1: Deck | D1: DNA library [ng µl-1] | E1: Amount in pool [ng] | F1: Required volume library [µl]
A2: 17 | B2: media+gw_a | C2: A3 | D2: 53 | E2: =$O$9 -> 65.1 | F2: =E2/D2 -> 1.2283019
A3: 18 | B3: media+gw_b | C3: A3 | D3: 26 | E3: =$O$9 -> 65.1 | F3: =E3/D3 -> 2.5038462
A4: 19 | B4: media+gw_d | C4: A3 | D4: 57 | E4: =$O$9 -> 65.1 | F4: =E4/D4 -> 1.1421053 | L4: Library diluted 1:1 in low-EDTA TE-buffer
A5: 20 | B5: methanol_a | C5: A3 | D5: 33.3 | E5: =$O$9 -> 65.1 | F5: =E5/D5 -> 1.954955
A6: 21 | B6: methanol_c | C6: A3 | D6: 33.5 | E6: =$O$9 -> 65.1 | F6: =E6/D6 -> 1.9432836
A7: 33 | B7: l3u | C7: B1 | D7: 29.8 | E7: =$O$9 -> 65.1 | F7: =E7/D7 -> 2.1845638
A8: 34 | B8: l2f | C8: B1 | D8: 54 | E8: =$O$9 -> 65.1 | F8: =E8/D8 -> 1.2055556 | K8: Number of samples | O8: =ROWS(A2:A34) -> 33
A9: 35 | B9: a4f | C9: B1 | D9: 3 | E9: =$O$9 -> 65.1 | F9: =E9/D9 -> 21.7 | G9: x | K9: DNA amount most concentrated library [ng] | O9: =1.5*Samples!K22 -> 65.1
A10: 36 | B10: KFM02a_2 | C10: B1 | D10: 35.9 | E10: =$O$9 -> 65.1 | F10: =E10/D10 -> 1.8133705 | K10: Final amount in library [ng] | O10: =O8*O9 -> 2148.3
A11: 37 | B11: KFM24_1 | C11: B1 | D11: 43.4 | E11: =$O$9 -> 65.1 | F11: =E11/D11 -> 1.5 | K11: Total volume undiluted library [µl] | O11: =SUM(F2:F34) -> 168.48135
A12: 38 | B12: KFM24_2 | C12: B1 | D12: 30.2 | E12: =$O$9 -> 65.1 | F12: =E12/D12 -> 2.1556291 | K12: Concentration library [ng µl-1] | O12: =O10/O11 -> 12.750966
A13: 39 | B13: KFM24_3 | C13: B1 | D13: 52 | E13: =$O$9 -> 65.1 | F13: =E13/D13 -> 1.2519231 | K13: Desired concentration [ng µl-1] | O13: 10
A14: 41 | B14: cosc_f1 | C14: B2 | D14: 56 | E14: =$O$9 -> 65.1 | F14: =E14/D14 -> 1.1625 | K14: Desired volume [µl] | O14: 40
A15: 43 | B15: l1f | C15: B2 | D15: 36.5 | E15: =$O$9 -> 65.1 | F15: =E15/D15 -> 1.7835616 | K15: Volume library for dilution [µl] | O15: =(O13*O14)/O12 -> 31.370171
A16: 44 | B16: l2u | C16: B2 | D16: 53 | E16: =$O$9 -> 65.1 | F16: =E16/D16 -> 1.2283019 | K16: Volume TE-buffer [µl] | O16: =50-O15 -> 18.629829
A17: 45 | B17: a4u | C17: B2 | D17: 48.8 | E17: =$O$9 -> 65.1 | F17: =E17/D17 -> 1.3340164
A18: 46 | B18: s2u | C18: B2 | D18: 43.3 | E18: =$O$9 -> 65.1 | F18: =E18/D18 -> 1.5034642 | K18: Qubit pool undiluted [ng µl-1] | O18: 19.9
A19: 47 | B19: media+oil_b | C19: B2 | D19: 8.05 | E19: =$O$9 -> 65.1 | F19: =E19/D19 -> 8.0869565 | K19: Qubit pool 1:1 in low-EDTA TE-buffer | O19: 9.06
A20: 49 | B20: l5u | C20: B3 | D20: 25 | E20: =$O$9 -> 65.1 | F20: =E20/D20 -> 2.604
A21: 50 | B21: cosc_f3 | C21: B3 | D21: 49.8 | E21: =$O$9 -> 65.1 | F21: =E21/D21 -> 1.3072289
A22: 51 | B22: cosc_f5 | C22: B3 | D22: 36.5 | E22: =$O$9 -> 65.1 | F22: =E22/D22 -> 1.7835616
A23: 52 | B23: a1u | C23: B3 | D23: 3.1 | E23: =$O$9 -> 65.1 | F23: =E23/D23 -> 21 | G23: x
A24: 54 | B24: s3f | C24: B3 | D24: 1.28 | E24: =$O$9 -> 65.1 | F24: 40 | G24: x
A25: 55 | B25: l6f | C25: B3 | D25: 9.14 | E25: =$O$9 -> 65.1 | F25: =E25/D25 -> 7.1225383
A26: 56 | B26: l7f | C26: B3 | D26: 2.86 | E26: =$O$9 -> 65.1 | F26: =E26/D26 -> 22.762238 | G26: x
A27: 57 | B27: methanol_d | C27: B4 | D27: 8.81 | E27: =$O$9 -> 65.1 | F27: =E27/D27 -> 7.3893303
A28: 58 | B28: media+gw+oil_c | C28: B4 | D28: 52 | E28: =$O$9 -> 65.1 | F28: =E28/D28 -> 1.2519231
A29: 59 | B29: media+gw+oil_b | C29: B4 | D29: 51 | E29: =$O$9 -> 65.1 | F29: =E29/D29 -> 1.2764706
A30: 60 | B30: a1f | C30: B4 | D30: 39.7 | E30: =$O$9 -> 65.1 | F30: =E30/D30 -> 1.6397985
A31: 61 | B31: KFM02a_3 | C31: B4 | D31: 56 | E31: =$O$9 -> 65.1 | F31: =E31/D31 -> 1.1625
A32: 62 | B32: KFM02a_5 | C32: B4 | D32: 52 | E32: =$O$9 -> 65.1 | F32: =E32/D32 -> 1.2519231
A33: 63 | B33: SA1420_SRM_a | C33: B4 | D33: 56 | E33: =$O$9 -> 65.1 | F33: =E33/D33 -> 1.1625
A34: 64 | B34: SA1420_SRM_b | C34: B4 | D34: 60 | E34: =$O$9 -> 65.1 | F34: =E34/D34 -> 1.085

Sheet UDI-8 bp indices
A1: TecanUDI_A
A2: Tecan ID | B2: Magic ref. | C2: All | D2: index1 | E2: index2 (FW) | F2: index2 REV (NextSeq) | I2: UDI-8 bp formatted | J2: UDI-10 bp formatted | N2: UDI-8 bp Scilife formatted | O2: UDI-10 bp Scilife formatted
A3: 1_UDI_A01 | B3: _A1 | C3: 1_UDI_A01_A1 | D3: CGCTACAT | E3: AACCTACG | F3: CGTAGGTT | H3: 17 | I3: GTACACCT-GAGACCAA | J3: GTACACCTAT-GAGACCAAAC | K3: =J3=O19 -> TRUE | M3: 1_UDI_A01 | N3: =_xlfn.TEXTJOIN("-",TRUE,D3,E3) -> CGCTACAT-AACCTACG | O3: =_xlfn.TEXTJOIN("-",TRUE,'UDI-10 bp indices'!B3,'UDI-10 bp indices'!C3) -> CGCTACATAT-AACCTACGAC
A4: 2_UDI_B01 | B4: _A1 | C4: 2_UDI_B01_A1 | D4: AATCCAGC | E4: GCATCCTA | F4: TAGGATGC | H4: 18 | I4: ACGAGAAC-ACAGTTCG | J4: ACGAGAACAT-ACAGTTCGAC | K4: =J4=O20 -> TRUE | M4: 2_UDI_B01 | N4: =_xlfn.TEXTJOIN("-",TRUE,D4,E4) -> AATCCAGC-GCATCCTA | O4: =_xlfn.TEXTJOIN("-",TRUE,'UDI-10 bp indices'!B4,'UDI-10 bp indices'!C4) -> AATCCAGCAT-GCATCCTAAC
A5: 3_UDI_C01 | B5: _A1 | C5: 3_UDI_C01_A1 | D5: CGTCTAAC | E5: CAACGAGT | F5: ACTCGTTG | H5: 19 | I5: CGACCTAA-CTAACCTG | J5: CGACCTAAAT-CTAACCTGAC | K5: =J5=O21 -> TRUE | M5: 3_UDI_C01 | N5: =_xlfn.TEXTJOIN("-",TRUE,D5,E5) -> CGTCTAAC-CAACGAGT | O5: =_xlfn.TEXTJOIN("-",TRUE,'UDI-10 bp indices'!B5,'UDI-10 bp indices'!C5) -> CGTCTAACAT-CAACGAGTAC
A6: 4_UDI_D01 | B6: _A1 | C6: 4_UDI_D01_A1 | D6: AACTCGGA | E6: TGCAAGAC | F6: GTCTTGCA | H6: 20 | I6: TACATCGG-TCCGATCA | J6: TACATCGGAT-TCCGATCAAC | K6: =J6=O22 -> TRUE | M6: 4_UDI_D01 | N6: =_xlfn.TEXTJOIN("-",TRUE,D6,E6) -> AACTCGGA-TGCAAGAC | O6: =_xlfn.TEXTJOIN("-",TRUE,'UDI-10 bp indices'!B6,'UDI-10 bp indices'!C6) -> AACTCGGAAT-TGCAAGACAC
A7: 5_UDI_E01 | B7: _A1 | C7: 5_UDI_E01_A1 | D7: GTCGAGAA | E7: CTTACAGC | F7: GCTGTAAG | H7: 21 | I7: ATCGTCTC-AGAAGGAC | J7: ATCGTCTCAT-AGAAGGACAC | K7: =J7=O23 -> TRUE | M7: 5_UDI_E01 | N7: =_xlfn.TEXTJOIN("-",TRUE,D7,E7) -> GTCGAGAA-CTTACAGC | O7: =_xlfn.TEXTJOIN("-",TRUE,'UDI-10 bp indices'!B7,'UDI-10 bp indices'!C7) -> GTCGAGAAAT-CTTACAGCAC
A8: 6_UDI_F01 | B8: _A1 | C8: 6_UDI_F01_A1 | D8: ACAACAGC | E8: ACCGACAA | F8: TTGTCGGT | H8: 33 | I8: AGGTTCCT-TCGAACCT | J8: AGGTTCCTAT-TCGAACCTAC | K8: =J8=O35 -> TRUE | M8: 6_UDI_F01 | N8: =_xlfn.TEXTJOIN("-",TRUE,D8,E8) -> ACAACAGC-ACCGACAA | O8: =_xlfn.TEXTJOIN("-",TRUE,'UDI-10 bp indices'!B8,'UDI-10 bp indices'!C8) -> ACAACAGCAT-ACCGACAAAC
A9: 7_UDI_G01 | B9: _A1 | C9: 7_UDI_G01_A1 | D9: ATGACAGG | E9: ACATGCCA | F9: TGGCATGT | H9: 34 | I9: GAACCTTC-CAAGGTAC | J9: GAACCTTCAT-CAAGGTACAC | K9: =J9=O36 -> TRUE | M9: 7_UDI_G01 | N9: =_xlfn.TEXTJOIN("-",TRUE,D9,E9) -> ATGACAGG-ACATGCCA | O9: =_xlfn.TEXTJOIN("-",TRUE,'UDI-10 bp indices'!B9,'UDI-10 bp indices'!C9) -> ATGACAGGAT-ACATGCCAAC
A10: 8_UDI_H01 | B10: _A1 | C10: 8_UDI_H01_A1 | D10: GCACACAA | E10: GAGCAATC | F10: GATTGCTC | H10: 35 | I10: AAGTCCTC-AGCTACCA | J10: AAGTCCTCAT-AGCTACCAAC | K10: =J10=O37 -> TRUE | M10: 8_UDI_H01 | N10: =_xlfn.TEXTJOIN("-",TRUE,D10,E10) -> GCACACAA-GAGCAATC | O10: =_xlfn.TEXTJOIN("-",TRUE,'UDI-10 bp indices'!B10,'UDI-10 bp indices'!C10) -> GCACACAAAT-GAGCAATCAC
A11: 9_UDI_A02 | B11: _A2 | C11: 9_UDI_A02_A2 | D11: CTCCTAGT | E11: CCTCATCT | F11: AGATGAGG | H11: 36 | I11: CCACAACA-CATCCAAG | J11: CCACAACAAT-CATCCAAGAC | K11: =J11=O38 -> TRUE | M11: 9_UDI_A02 | N11: =_xlfn.TEXTJOIN("-",TRUE,D11,E11) -> CTCCTAGT-CCTCATCT | O11: =_xlfn.TEXTJOIN("-",TRUE,'UDI-10 bp indices'!B11,'UDI-10 bp indices'!C11) -> CTCCTAGTAT-CCTCATCTAC
A12: 10_UDI_B02 | B12: _A2 | C12: 10_UDI_B02_A2 | D12: TCTTCGAC | E12: TACTGCTC | F12: GAGCAGTA | H12: 37 | I12: ATAACGCC-CTCACCAA | J12: ATAACGCCAT-CTCACCAAAC | K12: =J12=O39 -> TRUE | M12: 10_UDI_B02 | N12: =_xlfn.TEXTJOIN("-",TRUE,D12,E12) -> TCTTCGAC-TACTGCTC | O12: =_xlfn.TEXTJOIN("-",TRUE,'UDI-10 bp indices'!B12,'UDI-10 bp indices'!C12) -> TCTTCGACAT-TACTGCTCAC
A13: 11_UDI_C02 | B13: _A2 | C13: 11_UDI_C02_A2 | D13: GACTACGA | E13: TTACCGAC | F13: GTCGGTAA | H13: 38 | I13: CCGGAATA-TCAGTAGG | J13: CCGGAATAAT-TCAGTAGGAC | K13: =J13=O40 -> TRUE | M13: 11_UDI_C02 | N13: =_xlfn.TEXTJOIN("-",TRUE,D13,E13) -> GACTACGA-TTACCGAC | O13: =_xlfn.TEXTJOIN("-",TRUE,'UDI-10 bp indices'!B13,'UDI-10 bp indices'!C13) -> GACTACGAAT-TTACCGACAC
A14: 12_UDI_D02 | B14: _A2 | C14: 12_UDI_D02_A2 | D14: ACTCCTAC | E14: CCGTAACT | F14: AGTTACGG | H14: 39 | I14: CCAAGTAG-GAACGTGA | J14: CCAAGTAGAT-GAACGTGAAC | K14: =J14=O41 -> TRUE | M14: 12_UDI_D02 | N14: =_xlfn.TEXTJOIN("-",TRUE,D14,E14) -> ACTCCTAC-CCGTAACT | O14: =_xlfn.TEXTJOIN("-",TRUE,'UDI-10 bp indices'!B14,'UDI-10 bp indices'!C14) -> ACTCCTACAT-CCGTAACTAC
A15: 13_UDI_E02 | B15: _A2 | C15: 13_UDI_E02_A2 | D15: CTTCCTTC | E15: TTCCAGGT | F15: ACCTGGAA | H15: 41 | I15: ACGCTTCT-CCTAAGTC | J15: ACGCTTCTAT-CCTAAGTCAC | K15: =J15=O43 -> TRUE | M15: 13_UDI_E02 | N15: =_xlfn.TEXTJOIN("-",TRUE,D15,E15) -> CTTCCTTC-TTCCAGGT | O15: =_xlfn.TEXTJOIN("-",TRUE,'UDI-10 bp indices'!B15,'UDI-10 bp indices'!C15) -> CTTCCTTCAT-TTCCAGGTAC
A16: 14_UDI_F02 | B16: _A2 | C16: 14_UDI_F02_A2 | D16: ACCATCCT | E16: CCATGAAC | F16: GTTCATGG | H16: 43 | I16: TGACAACC-GTCAACAG | J16: TGACAACCAT-GTCAACAGAC | K16: =O45=J16 -> TRUE | M16: 14_UDI_F02 | N16: =_xlfn.TEXTJOIN("-",TRUE,D16,E16) -> ACCATCCT-CCATGAAC | O16: =_xlfn.TEXTJOIN("-",TRUE,'UDI-10 bp indices'!B16,'UDI-10 bp indices'!C16) -> ACCATCCTAT-CCATGAACAC
A17: 15_UDI_G02 | B17: _A2 | C17: 15_UDI_G02_A2 | D17: CGTCCATT | E17: TTCCTCCT | F17: AGGAGGAA | H17: 44 | I17: CAGTGCTT-ACACCTCA | J17: CAGTGCTTAT-ACACCTCAAC | K17: =O46=J17 -> TRUE | M17: 15_UDI_G02 | N17: =_xlfn.TEXTJOIN("-",TRUE,D17,E17) -> CGTCCATT-TTCCTCCT | O17: =_xlfn.TEXTJOIN("-",TRUE,'UDI-10 bp indices'!B17,'UDI-10 bp indices'!C17) -> CGTCCATTAT-TTCCTCCTAC
A18: 16_UDI_H02 | B18: _A2 | C18: 16_UDI_H02_A2 | D18: AACTTGCC | E18: CCAACTTC | F18: GAAGTTGG | H18: 45 | I18: TCACTCGA-TATGGCAC | J18: TCACTCGAAT-TATGGCACAC | K18: =O47=J18 -> TRUE | M18: 16_UDI_H02 | N18: =_xlfn.TEXTJOIN("-",TRUE,D18,E18) -> AACTTGCC-CCAACTTC | O18: =_xlfn.TEXTJOIN("-",TRUE,'UDI-10 bp indices'!B18,'UDI-10 bp indices'!C18) -> AACTTGCCAT-CCAACTTCAC
A19: 17_UDI_A03 | B19: _A3 | C19: 17_UDI_A03_A3 | D19: GTACACCT | E19: GAGACCAA | F19: TTGGTCTC | H19: 46 | I19: CTGACTAC-CGCAATGT | J19: CTGACTACAT-CGCAATGTAC | K19: =O48=J19 -> TRUE | M19: 17_UDI_A03 | N19: =_xlfn.TEXTJOIN("-",TRUE,D19,E19) -> GTACACCT-GAGACCAA | O19: =_xlfn.TEXTJOIN("-",TRUE,'UDI-10 bp indices'!B19,'UDI-10 bp indices'!C19) -> GTACACCTAT-GAGACCAAAC
A20: 18_UDI_B03 | B20: _A3 | C20: 18_UDI_B03_A3 | D20: ACGAGAAC | E20: ACAGTTCG | F20: CGAACTGT | H20: 47 | I20: GTGATCCA-ACTCAACG | J20: GTGATCCAAT-ACTCAACGAC | K20: =O49=J20 -> TRUE | M20: 18_UDI_B03 | N20: =_xlfn.TEXTJOIN("-",TRUE,D20,E20) -> ACGAGAAC-ACAGTTCG | O20: =_xlfn.TEXTJOIN("-",TRUE,'UDI-10 bp indices'!B20,'UDI-10 bp indices'!C20) -> ACGAGAACAT-ACAGTTCGAC
A21: 19_UDI_C03 | B21: _A3 | C21: 19_UDI_C03_A3 | D21: CGACCTAA | E21: CTAACCTG | F21: CAGGTTAG | H21: 49 | I21: TGCTGTGA-CACGATTC | J21: TGCTGTGAAT-CACGATTCAC | K21: =O51=J21 -> TRUE | M21: 19_UDI_C03 | N21: =_xlfn.TEXTJOIN("-",TRUE,D21,E21) -> CGACCTAA-CTAACCTG | O21: =_xlfn.TEXTJOIN("-",TRUE,'UDI-10 bp indices'!B21,'UDI-10 bp indices'!C21) -> CGACCTAAAT-CTAACCTGAC
A22: 20_UDI_D03 | B22: _A3 | C22: 20_UDI_D03_A3 | D22: TACATCGG | E22: TCCGATCA | F22: TGATCGGA | H22: 50 | I22: CAACACAG-AGAAGCCT | J22: CAACACAGAT-AGAAGCCTAC | K22: =O52=J22 -> TRUE | M22: 20_UDI_D03 | N22: =_xlfn.TEXTJOIN("-",TRUE,D22,E22) -> TACATCGG-TCCGATCA | O22: =_xlfn.TEXTJOIN("-",TRUE,'UDI-10 bp indices'!B22,'UDI-10 bp indices'!C22) -> TACATCGGAT-TCCGATCAAC
A23: 21_UDI_E03 | B23: _A3 | C23: 21_UDI_E03_A3 | D23: ATCGTCTC | E23: AGAAGGAC | F23: GTCCTTCT | H23: 51 | I23: CCACATTG-TACTCCAG | J23: CCACATTGAT-TACTCCAGAC | K23: =O53=J23 -> TRUE | M23: 21_UDI_E03 | N23: =_xlfn.TEXTJOIN("-",TRUE,D23,E23) -> ATCGTCTC-AGAAGGAC | O23: =_xlfn.TEXTJOIN("-",TRUE,'UDI-10 bp indices'!B23,'UDI-10 bp indices'!C23) -> ATCGTCTCAT-AGAAGGACAC
A24: 22_UDI_F03 | B24: _A3 | C24: 22_UDI_F03_A3 | D24: CCAACACT | E24: GACGAACT | F24: AGTTCGTC | H24: 52 | I24: TAGTGCCA-CGTCAAGA | J24: TAGTGCCAAT-CGTCAAGAAC | K24: =O54=J24 -> TRUE | M24: 22_UDI_F03 | N24: =_xlfn.TEXTJOIN("-",TRUE,D24,E24) -> CCAACACT-GACGAACT | O24: =_xlfn.TEXTJOIN("-",TRUE,'UDI-10 bp indices'!B24,'UDI-10 bp indices'!C24) -> CCAACACTAT-GACGAACTAC
A25: 23_UDI_G03 | B25: _A3 | C25: 23_UDI_G03_A3 | D25: TCTAGGAG | E25: TTGCAACG | F25: CGTTGCAA | H25: 54 | I25: CTACATCC-TCACCTAG | J25: CTACATCCAT-TCACCTAGAC | K25: =J25=O56 -> TRUE | M25: 23_UDI_G03 | N25: =_xlfn.TEXTJOIN("-",TRUE,D25,E25) -> TCTAGGAG-TTGCAACG | O25: =_xlfn.TEXTJOIN("-",TRUE,'UDI-10 bp indices'!B25,'UDI-10 bp indices'!C25) -> TCTAGGAGAT-TTGCAACGAC
A26: 24_UDI_H03 | B26: _A3 | C26: 24_UDI_H03_A3 | D26: CTCGAACA | E26: CCAACGAA | F26: TTCGTTGG | H26: 55 | I26: CATACGGA-AACACCAC | J26: CATACGGAAT-AACACCACAC | K26: =J26=O57 -> TRUE | M26: 24_UDI_H03 | N26: =_xlfn.TEXTJOIN("-",TRUE,D26,E26) -> CTCGAACA-CCAACGAA | O26: =_xlfn.TEXTJOIN("-",TRUE,'UDI-10 bp indices'!B26,'UDI-10 bp indices'!C26) -> CTCGAACAAT-CCAACGAAAC
A27: 25_UDI_A04 | B27: _A4 | C27: 25_UDI_A04_A4 | D27: ACGGACTT | E27: ATCGGAGA | F27: TCTCCGAT | H27: 56 | I27: TGCGTAAC-CGTCTTCA | J27: TGCGTAACAT-CGTCTTCAAC | K27: =J27=O58 -> TRUE | M27: 25_UDI_A04 | N27: =_xlfn.TEXTJOIN("-",TRUE,D27,E27) -> ACGGACTT-ATCGGAGA | O27: =_xlfn.TEXTJOIN("-",TRUE,'UDI-10 bp indices'!B27,'UDI-10 bp indices'!C27) -> ACGGACTTAT-ATCGGAGAAC
A28: 26_UDI_B04 | B28: _A4 | C28: 26_UDI_B04_A4 | D28: CTAAGACC | E28: CCTAACAG | F28: CTGTTAGG | H28: 57 | I28: CAGGTTCA-AACGTAGC | J28: CAGGTTCAAT-AACGTAGCAC | K28: =J28=O59 -> TRUE | M28: 26_UDI_B04 | N28: =_xlfn.TEXTJOIN("-",TRUE,D28,E28) -> CTAAGACC-CCTAACAG | O28: =_xlfn.TEXTJOIN("-",TRUE,'UDI-10 bp indices'!B28,'UDI-10 bp indices'!C28) -> CTAAGACCAT-CCTAACAGAC
A29: 27_UDI_C04 | B29: _A4 | C29: 27_UDI_C04_A4 | D29: AACCGAAC | E29: CATACTCG | F29: CGAGTATG | H29: 58 | I29: AGAACCAG-GCAACCAT | J29: AGAACCAGAT-GCAACCATAC | K29: =J29=O60 -> TRUE | M29: 27_UDI_C04 | N29: =_xlfn.TEXTJOIN("-",TRUE,D29,E29) -> AACCGAAC-CATACTCG | O29: =_xlfn.TEXTJOIN("-",TRUE,'UDI-10 bp indices'!B29,'UDI-10 bp indices'!C29) -> AACCGAACAT-CATACTCGAC
A30: 28_UDI_D04 | B30: _A4 | C30: 28_UDI_D04_A4 | D30: CCTTAGGT | E30: TGCCTCAA | F30: TTGAGGCA | H30: 59 | I30: GAATGGCA-GATCCACT | J30: GAATGGCAAT-GATCCACTAC | K30: =J30=O61 -> TRUE | M30: 28_UDI_D04 | N30: =_xlfn.TEXTJOIN("-",TRUE,D30,E30) -> CCTTAGGT-TGCCTCAA | O30: =_xlfn.TEXTJOIN("-",TRUE,'UDI-10 bp indices'!B30,'UDI-10 bp indices'!C30) -> CCTTAGGTAT-TGCCTCAAAC
A31: 29_UDI_E04 | B31: _A4 | C31: 29_UDI_E04_A4 | D31: CCTATACC | E31: TACAGAGC | F31: GCTCTGTA | H31: 60 | I31: AGGCAATG-ACCTAGAC | J31: AGGCAATGAT-ACCTAGACAC | K31: =J31=O62 -> TRUE | M31: 29_UDI_E04 | N31: =_xlfn.TEXTJOIN("-",TRUE,D31,E31) -> CCTATACC-TACAGAGC | O31: =_xlfn.TEXTJOIN("-",TRUE,'UDI-10 bp indices'!B31,'UDI-10 bp indices'!C31) -> CCTATACCAT-TACAGAGCAC
A32: 30_UDI_F04 | B32: _A4 | C32: 30_UDI_F04_A4 | D32: AACGCCTT | E32: CGAGAGAA | F32: TTCTCTCG | H32: 61 | I32: TAGGAGCT-CTAGCAGT | J32: TAGGAGCTAT-CTAGCAGTAC | K32: =J32=O63 -> TRUE | M32: 30_UDI_F04 | N32: =_xlfn.TEXTJOIN("-",TRUE,D32,E32) -> AACGCCTT-CGAGAGAA | O32: =_xlfn.TEXTJOIN("-",TRUE,'UDI-10 bp indices'!B32,'UDI-10 bp indices'!C32) -> AACGCCTTAT-CGAGAGAAAC
A33: 31_UDI_G04 | B33: _A4 | C33: 31_UDI_G04_A4 | D33: TCCATTGC | E33: AGGTAGGA | F33: TCCTACCT | H33: 62 | I33: CGAACAAC-TCGATGAC | J33: CGAACAACAT-TCGATGACAC | K33: =J33=O64 -> TRUE | M33: 31_UDI_G04 | N33: =_xlfn.TEXTJOIN("-",TRUE,D33,E33) -> TCCATTGC-AGGTAGGA | O33: =_xlfn.TEXTJOIN("-",TRUE,'UDI-10 bp indices'!B33,'UDI-10 bp indices'!C33) -> TCCATTGCAT-AGGTAGGAAC
A34: 32_UDI_H04 | B34: _A4 | C34: 32_UDI_H04_A4 | D34: CAAGCCAA | E34: GAACGAAG | F34: CTTCGTTC | H34: 63 | I34: CATTCGTC-TTGGTGCA | J34: CATTCGTCAT-TTGGTGCAAC | K34: =J34=O65 -> TRUE | M34: 32_UDI_H04 | N34: =_xlfn.TEXTJOIN("-",TRUE,D34,E34) -> CAAGCCAA-GAACGAAG | O34: =_xlfn.TEXTJOIN("-",TRUE,'UDI-10 bp indices'!B34,'UDI-10 bp indices'!C34) -> CAAGCCAAAT-GAACGAAGAC
A35: 33_UDI_A05 | B35: _B1 | C35: 33_UDI_A05_B1 | D35: AGGTTCCT | E35: TCGAACCT | F35: AGGTTCGA | H35: 64 | I35: AGCCAACT-AGTGCATC | J35: AGCCAACTAT-AGTGCATCAC | K35: =J35=O66 -> TRUE | M35: 33_UDI_A05 | N35: =_xlfn.TEXTJOIN("-",TRUE,D35,E35) -> AGGTTCCT-TCGAACCT | O35: =_xlfn.TEXTJOIN("-",TRUE,'UDI-10 bp indices'!B35,'UDI-10 bp indices'!C35) -> AGGTTCCTAT-TCGAACCTAC
A36: 34_UDI_B05 | B36: _B1 | C36: 34_UDI_B05_B1 | D36: GAACCTTC | E36: CAAGGTAC | F36: GTACCTTG | M36: 34_UDI_B05 | N36: =_xlfn.TEXTJOIN("-",TRUE,D36,E36) -> GAACCTTC-CAAGGTAC | O36: =_xlfn.TEXTJOIN("-",TRUE,'UDI-10 bp indices'!B36,'UDI-10 bp indices'!C36) -> GAACCTTCAT-CAAGGTACAC
A37: 35_UDI_C05 | B37: _B1 | C37: 35_UDI_C05_B1 | D37: AAGTCCTC | E37: AGCTACCA | F37: TGGTAGCT | M37: 35_UDI_C05 | N37: =_xlfn.TEXTJOIN("-",TRUE,D37,E37) -> AAGTCCTC-AGCTACCA | O37: =_xlfn.TEXTJOIN("-",TRUE,'UDI-10 bp indices'!B37,'UDI-10 bp indices'!C37) -> AAGTCCTCAT-AGCTACCAAC
A38: 36_UDI_D05 | B38: _B1 | C38: 36_UDI_D05_B1 | D38: CCACAACA | E38: CATCCAAG | F38: CTTGGATG | M38: 36_UDI_D05 | N38: =_xlfn.TEXTJOIN("-",TRUE,D38,E38) -> CCACAACA-CATCCAAG | O38: =_xlfn.TEXTJOIN("-",TRUE,'UDI-10 bp indices'!B38,'UDI-10 bp indices'!C38) -> CCACAACAAT-CATCCAAGAC
A39: 37_UDI_E05 | B39: _B1 | C39: 37_UDI_E05_B1 | D39: ATAACGCC | E39: CTCACCAA | F39: TTGGTGAG | M39: 37_UDI_E05 | N39: =_xlfn.TEXTJOIN("-",TRUE,D39,E39) -> ATAACGCC-CTCACCAA | O39: =_xlfn.TEXTJOIN("-",TRUE,'UDI-10 bp indices'!B39,'UDI-10 bp indices'!C39) -> ATAACGCCAT-CTCACCAAAC
A40: 38_UDI_F05 | B40: _B1 | C40: 38_UDI_F05_B1 | D40: CCGGAATA | E40: TCAGTAGG | F40: CCTACTGA | M40: 38_UDI_F05 | N40: =_xlfn.TEXTJOIN("-",TRUE,D40,E40) -> CCGGAATA-TCAGTAGG | O40: =_xlfn.TEXTJOIN("-",TRUE,'UDI-10 bp indices'!B40,'UDI-10 bp indices'!C40) -> CCGGAATAAT-TCAGTAGGAC
...

Sheet UDI-10 bp indices
A2: All | B2: index1 | C2: index2 (FW) | D2: index2 REV (NextSeq)
A3: 1_UDI_A01_A1 | B3: CGCTACATAT | C3: AACCTACGAC | D3: CGTAGGTTGT
A4: 2_UDI_B01_A1 | B4: AATCCAGCAT | C4: GCATCCTAAC | D4: TAGGATGCGT
A5: 3_UDI_C01_A1 | B5: CGTCTAACAT | C5: CAACGAGTAC | D5: ACTCGTTGGT
A6: 4_UDI_D01_A1 | B6: AACTCGGAAT | C6: TGCAAGACAC | D6: GTCTTGCAGT
A7: 5_UDI_E01_A1 | B7: GTCGAGAAAT | C7: CTTACAGCAC | D7: GCTGTAAGGT
A8: 6_UDI_F01_A1 | B8: ACAACAGCAT | C8: ACCGACAAAC | D8: TTGTCGGTGT
A9: 7_UDI_G01_A1 | B9: ATGACAGGAT | C9: ACATGCCAAC | D9: TGGCATGTGT
A10: 8_UDI_H01_A1 | B10: GCACACAAAT | C10: GAGCAATCAC | D10: GATTGCTCGT
A11: 9_UDI_A02_A2 | B11: CTCCTAGTAT | C11: CCTCATCTAC | D11: AGATGAGGGT
A12: 10_UDI_B02_A2 | B12: TCTTCGACAT | C12: TACTGCTCAC | D12: GAGCAGTAGT
A13: 11_UDI_C02_A2 | B13: GACTACGAAT | C13: TTACCGACAC | D13: GTCGGTAAGT
... A98: 96_UDI_H12_C4 | B98: ATCTGACCAT | C98: GTACGATCAC | D98: GATCGTACGT
